<?xml version="1.0" encoding="UTF-8"?>
<testng-results ignored="0" total="21" passed="3" failed="17" skipped="1">
  <reporter-output>
  </reporter-output>
  <suite started-at="2025-01-24T18:04:24Z" name="Suite" finished-at="2025-01-24T18:06:52Z" duration-ms="147915">
    <groups>
      <group name="ErrorHandling">
        <method signature="ErrorValidations.validateAllErrorMessages(java.util.HashMap)[pri:0, instance:testCases.ErrorValidations@503ecb24]" name="validateAllErrorMessages" class="testCases.ErrorValidations"/>
      </group> <!-- ErrorHandling -->
    </groups>
    <test started-at="2025-01-24T18:04:24Z" name="Submit Order" finished-at="2025-01-24T18:04:52Z" duration-ms="27808">
      <class name="testCases.TestOrderCaseAmazon">
        <test-method is-config="true" signature="initializeDriver()[pri:0, instance:testCases.TestOrderCaseAmazon@6e4566f1]" started-at="2025-01-24T18:04:24Z" name="initializeDriver" finished-at="2025-01-24T18:04:27Z" duration-ms="2772" status="PASS">
          <reporter-output>
          </reporter-output>
        </test-method> <!-- initializeDriver -->
        <test-method is-config="true" signature="beforeClass()[pri:0, instance:testCases.TestOrderCaseAmazon@6e4566f1]" started-at="2025-01-24T18:04:27Z" name="beforeClass" finished-at="2025-01-24T18:04:27Z" duration-ms="1" status="PASS">
          <reporter-output>
          </reporter-output>
        </test-method> <!-- beforeClass -->
        <test-method is-config="true" signature="launchTheApplication()[pri:0, instance:testCases.TestOrderCaseAmazon@6e4566f1]" started-at="2025-01-24T18:04:27Z" name="launchTheApplication" finished-at="2025-01-24T18:04:33Z" duration-ms="5760" status="PASS">
          <reporter-output>
          </reporter-output>
        </test-method> <!-- launchTheApplication -->
        <test-method signature="test()[pri:0, instance:testCases.TestOrderCaseAmazon@6e4566f1]" started-at="2025-01-24T18:04:33Z" name="test" finished-at="2025-01-24T18:04:46Z" duration-ms="13022" status="PASS">
          <reporter-output>
          </reporter-output>
        </test-method> <!-- test -->
        <test-method is-config="true" signature="launchTheApplication()[pri:0, instance:testCases.TestOrderCaseAmazon@6e4566f1]" started-at="2025-01-24T18:04:46Z" name="launchTheApplication" finished-at="2025-01-24T18:04:51Z" duration-ms="5813" status="PASS">
          <reporter-output>
          </reporter-output>
        </test-method> <!-- launchTheApplication -->
        <test-method signature="searchProduct()[pri:0, instance:testCases.TestOrderCaseAmazon@6e4566f1]" started-at="2025-01-24T18:04:51Z" name="searchProduct" finished-at="2025-01-24T18:04:51Z" depends-on-methods="testCases.TestOrderCaseAmazon.test" duration-ms="1" status="PASS">
          <reporter-output>
          </reporter-output>
        </test-method> <!-- searchProduct -->
        <test-method is-config="true" signature="tearDown()[pri:0, instance:testCases.TestOrderCaseAmazon@6e4566f1]" started-at="2025-01-24T18:04:51Z" name="tearDown" finished-at="2025-01-24T18:04:52Z" duration-ms="414" status="PASS">
          <reporter-output>
          </reporter-output>
        </test-method> <!-- tearDown -->
      </class> <!-- testCases.TestOrderCaseAmazon -->
    </test> <!-- Submit Order -->
    <test started-at="2025-01-24T18:04:24Z" name="Error Validations" finished-at="2025-01-24T18:06:52Z" duration-ms="147915">
      <class name="testCases.ErrorValidations">
        <test-method is-config="true" signature="initializeDriver()[pri:0, instance:testCases.ErrorValidations@503ecb24]" started-at="2025-01-24T18:04:24Z" name="initializeDriver" finished-at="2025-01-24T18:04:27Z" duration-ms="2772" status="PASS">
          <reporter-output>
          </reporter-output>
        </test-method> <!-- initializeDriver -->
        <test-method is-config="true" signature="beforeClass()[pri:0, instance:testCases.ErrorValidations@503ecb24]" started-at="2025-01-24T18:04:27Z" name="beforeClass" finished-at="2025-01-24T18:04:27Z" duration-ms="1" status="PASS">
          <reporter-output>
          </reporter-output>
        </test-method> <!-- beforeClass -->
        <test-method is-config="true" signature="launchTheApplication()[pri:0, instance:testCases.ErrorValidations@503ecb24]" started-at="2025-01-24T18:04:27Z" name="launchTheApplication" finished-at="2025-01-24T18:04:33Z" duration-ms="5447" status="PASS">
          <reporter-output>
          </reporter-output>
        </test-method> <!-- launchTheApplication -->
        <test-method signature="validateAllErrorMessages(java.util.HashMap)[pri:0, instance:testCases.ErrorValidations@503ecb24]" started-at="2025-01-24T18:04:33Z" name="validateAllErrorMessages" data-provider="getData" finished-at="2025-01-24T18:04:36Z" duration-ms="2766" status="SKIP">
          <params>
            <param index="0">
              <value>
                <![CDATA[{loginData=ad@}]]>
              </value>
            </param>
          </params>
          <exception class="java.lang.AssertionError">
            <message>
              <![CDATA[expected [true] but found [false]]]>
            </message>
            <full-stacktrace>
              <![CDATA[java.lang.AssertionError: expected [true] but found [false]
at org.testng.Assert.fail(Assert.java:96)
at org.testng.Assert.failNotEquals(Assert.java:776)
at org.testng.Assert.assertTrue(Assert.java:44)
at org.testng.Assert.assertTrue(Assert.java:54)
at testCases.ErrorValidations.validateAllErrorMessages(ErrorValidations.java:35)
at java.base/jdk.internal.reflect.DirectMethodHandleAccessor.invoke(DirectMethodHandleAccessor.java:104)
at java.base/java.lang.reflect.Method.invoke(Method.java:577)
at org.testng.internal.MethodInvocationHelper.invokeMethod(MethodInvocationHelper.java:124)
at org.testng.internal.Invoker.invokeMethod(Invoker.java:583)
at org.testng.internal.Invoker.invokeTestMethod(Invoker.java:719)
at org.testng.internal.Invoker.invokeTestMethods(Invoker.java:989)
at org.testng.internal.TestMethodWorker.invokeTestMethods(TestMethodWorker.java:125)
at org.testng.internal.TestMethodWorker.run(TestMethodWorker.java:109)
at org.testng.TestRunner.privateRun(TestRunner.java:648)
at org.testng.TestRunner.run(TestRunner.java:505)
at org.testng.SuiteRunner.runTest(SuiteRunner.java:455)
at org.testng.SuiteRunner.access$000(SuiteRunner.java:40)
at org.testng.SuiteRunner$SuiteWorker.run(SuiteRunner.java:489)
at org.testng.internal.thread.ThreadUtil$1.call(ThreadUtil.java:52)
at java.base/java.util.concurrent.FutureTask.run(FutureTask.java:264)
at java.base/java.util.concurrent.ThreadPoolExecutor.runWorker(ThreadPoolExecutor.java:1136)
at java.base/java.util.concurrent.ThreadPoolExecutor$Worker.run(ThreadPoolExecutor.java:635)
at java.base/java.lang.Thread.run(Thread.java:833)
]]>
            </full-stacktrace>
          </exception> <!-- java.lang.AssertionError -->
          <reporter-output>
          </reporter-output>
        </test-method> <!-- validateAllErrorMessages -->
        <test-method is-config="true" signature="launchTheApplication()[pri:0, instance:testCases.ErrorValidations@503ecb24]" started-at="2025-01-24T18:04:36Z" name="launchTheApplication" finished-at="2025-01-24T18:04:42Z" duration-ms="6152" status="PASS">
          <reporter-output>
          </reporter-output>
        </test-method> <!-- launchTheApplication -->
        <test-method signature="validateAllErrorMessages(java.util.HashMap)[pri:0, instance:testCases.ErrorValidations@503ecb24]" started-at="2025-01-24T18:04:42Z" name="validateAllErrorMessages" data-provider="getData" finished-at="2025-01-24T18:04:44Z" duration-ms="2233" status="FAIL">
          <params>
            <param index="0">
              <value>
                <![CDATA[{loginData=ad@}]]>
              </value>
            </param>
          </params>
          <exception class="java.lang.AssertionError">
            <message>
              <![CDATA[expected [true] but found [false]]]>
            </message>
            <full-stacktrace>
              <![CDATA[java.lang.AssertionError: expected [true] but found [false]
at org.testng.Assert.fail(Assert.java:96)
at org.testng.Assert.failNotEquals(Assert.java:776)
at org.testng.Assert.assertTrue(Assert.java:44)
at org.testng.Assert.assertTrue(Assert.java:54)
at testCases.ErrorValidations.validateAllErrorMessages(ErrorValidations.java:35)
at java.base/jdk.internal.reflect.DirectMethodHandleAccessor.invoke(DirectMethodHandleAccessor.java:104)
at java.base/java.lang.reflect.Method.invoke(Method.java:577)
at org.testng.internal.MethodInvocationHelper.invokeMethod(MethodInvocationHelper.java:124)
at org.testng.internal.Invoker.invokeMethod(Invoker.java:583)
at org.testng.internal.Invoker.retryFailed(Invoker.java:839)
at org.testng.internal.Invoker.invokeTestMethods(Invoker.java:1010)
at org.testng.internal.TestMethodWorker.invokeTestMethods(TestMethodWorker.java:125)
at org.testng.internal.TestMethodWorker.run(TestMethodWorker.java:109)
at org.testng.TestRunner.privateRun(TestRunner.java:648)
at org.testng.TestRunner.run(TestRunner.java:505)
at org.testng.SuiteRunner.runTest(SuiteRunner.java:455)
at org.testng.SuiteRunner.access$000(SuiteRunner.java:40)
at org.testng.SuiteRunner$SuiteWorker.run(SuiteRunner.java:489)
at org.testng.internal.thread.ThreadUtil$1.call(ThreadUtil.java:52)
at java.base/java.util.concurrent.FutureTask.run(FutureTask.java:264)
at java.base/java.util.concurrent.ThreadPoolExecutor.runWorker(ThreadPoolExecutor.java:1136)
at java.base/java.util.concurrent.ThreadPoolExecutor$Worker.run(ThreadPoolExecutor.java:635)
at java.base/java.lang.Thread.run(Thread.java:833)
]]>
            </full-stacktrace>
          </exception> <!-- java.lang.AssertionError -->
          <reporter-output>
          </reporter-output>
        </test-method> <!-- validateAllErrorMessages -->
        <test-method is-config="true" signature="launchTheApplication()[pri:0, instance:testCases.ErrorValidations@503ecb24]" started-at="2025-01-24T18:04:44Z" name="launchTheApplication" finished-at="2025-01-24T18:04:50Z" duration-ms="5722" status="PASS">
          <reporter-output>
          </reporter-output>
        </test-method> <!-- launchTheApplication -->
        <test-method signature="validateAllErrorMessages(java.util.HashMap)[pri:0, instance:testCases.ErrorValidations@503ecb24]" started-at="2025-01-24T18:04:50Z" name="validateAllErrorMessages" data-provider="getData" finished-at="2025-01-24T18:04:52Z" duration-ms="2057" status="FAIL">
          <params>
            <param index="0">
              <value>
                <![CDATA[{loginData=pwe}]]>
              </value>
            </param>
          </params>
          <exception class="java.lang.AssertionError">
            <message>
              <![CDATA[expected [true] but found [false]]]>
            </message>
            <full-stacktrace>
              <![CDATA[java.lang.AssertionError: expected [true] but found [false]
at org.testng.Assert.fail(Assert.java:96)
at org.testng.Assert.failNotEquals(Assert.java:776)
at org.testng.Assert.assertTrue(Assert.java:44)
at org.testng.Assert.assertTrue(Assert.java:54)
at testCases.ErrorValidations.validateAllErrorMessages(ErrorValidations.java:35)
at java.base/jdk.internal.reflect.DirectMethodHandleAccessor.invoke(DirectMethodHandleAccessor.java:104)
at java.base/java.lang.reflect.Method.invoke(Method.java:577)
at org.testng.internal.MethodInvocationHelper.invokeMethod(MethodInvocationHelper.java:124)
at org.testng.internal.Invoker.invokeMethod(Invoker.java:583)
at org.testng.internal.Invoker.invokeTestMethod(Invoker.java:719)
at org.testng.internal.Invoker.invokeTestMethods(Invoker.java:989)
at org.testng.internal.TestMethodWorker.invokeTestMethods(TestMethodWorker.java:125)
at org.testng.internal.TestMethodWorker.run(TestMethodWorker.java:109)
at org.testng.TestRunner.privateRun(TestRunner.java:648)
at org.testng.TestRunner.run(TestRunner.java:505)
at org.testng.SuiteRunner.runTest(SuiteRunner.java:455)
at org.testng.SuiteRunner.access$000(SuiteRunner.java:40)
at org.testng.SuiteRunner$SuiteWorker.run(SuiteRunner.java:489)
at org.testng.internal.thread.ThreadUtil$1.call(ThreadUtil.java:52)
at java.base/java.util.concurrent.FutureTask.run(FutureTask.java:264)
at java.base/java.util.concurrent.ThreadPoolExecutor.runWorker(ThreadPoolExecutor.java:1136)
at java.base/java.util.concurrent.ThreadPoolExecutor$Worker.run(ThreadPoolExecutor.java:635)
at java.base/java.lang.Thread.run(Thread.java:833)
]]>
            </full-stacktrace>
          </exception> <!-- java.lang.AssertionError -->
          <reporter-output>
          </reporter-output>
        </test-method> <!-- validateAllErrorMessages -->
        <test-method is-config="true" signature="launchTheApplication()[pri:0, instance:testCases.ErrorValidations@503ecb24]" started-at="2025-01-24T18:04:52Z" name="launchTheApplication" finished-at="2025-01-24T18:04:57Z" duration-ms="5298" status="PASS">
          <reporter-output>
          </reporter-output>
        </test-method> <!-- launchTheApplication -->
        <test-method signature="validateAllErrorMessages(java.util.HashMap)[pri:0, instance:testCases.ErrorValidations@503ecb24]" started-at="2025-01-24T18:04:57Z" name="validateAllErrorMessages" data-provider="getData" finished-at="2025-01-24T18:04:59Z" duration-ms="2072" status="FAIL">
          <params>
            <param index="0">
              <value>
                <![CDATA[{loginData=pwe}]]>
              </value>
            </param>
          </params>
          <exception class="java.lang.AssertionError">
            <message>
              <![CDATA[expected [true] but found [false]]]>
            </message>
            <full-stacktrace>
              <![CDATA[java.lang.AssertionError: expected [true] but found [false]
at org.testng.Assert.fail(Assert.java:96)
at org.testng.Assert.failNotEquals(Assert.java:776)
at org.testng.Assert.assertTrue(Assert.java:44)
at org.testng.Assert.assertTrue(Assert.java:54)
at testCases.ErrorValidations.validateAllErrorMessages(ErrorValidations.java:35)
at java.base/jdk.internal.reflect.DirectMethodHandleAccessor.invoke(DirectMethodHandleAccessor.java:104)
at java.base/java.lang.reflect.Method.invoke(Method.java:577)
at org.testng.internal.MethodInvocationHelper.invokeMethod(MethodInvocationHelper.java:124)
at org.testng.internal.Invoker.invokeMethod(Invoker.java:583)
at org.testng.internal.Invoker.retryFailed(Invoker.java:839)
at org.testng.internal.Invoker.invokeTestMethods(Invoker.java:1010)
at org.testng.internal.TestMethodWorker.invokeTestMethods(TestMethodWorker.java:125)
at org.testng.internal.TestMethodWorker.run(TestMethodWorker.java:109)
at org.testng.TestRunner.privateRun(TestRunner.java:648)
at org.testng.TestRunner.run(TestRunner.java:505)
at org.testng.SuiteRunner.runTest(SuiteRunner.java:455)
at org.testng.SuiteRunner.access$000(SuiteRunner.java:40)
at org.testng.SuiteRunner$SuiteWorker.run(SuiteRunner.java:489)
at org.testng.internal.thread.ThreadUtil$1.call(ThreadUtil.java:52)
at java.base/java.util.concurrent.FutureTask.run(FutureTask.java:264)
at java.base/java.util.concurrent.ThreadPoolExecutor.runWorker(ThreadPoolExecutor.java:1136)
at java.base/java.util.concurrent.ThreadPoolExecutor$Worker.run(ThreadPoolExecutor.java:635)
at java.base/java.lang.Thread.run(Thread.java:833)
]]>
            </full-stacktrace>
          </exception> <!-- java.lang.AssertionError -->
          <reporter-output>
          </reporter-output>
        </test-method> <!-- validateAllErrorMessages -->
        <test-method is-config="true" signature="launchTheApplication()[pri:0, instance:testCases.ErrorValidations@503ecb24]" started-at="2025-01-24T18:05:00Z" name="launchTheApplication" finished-at="2025-01-24T18:05:05Z" duration-ms="5200" status="PASS">
          <reporter-output>
          </reporter-output>
        </test-method> <!-- launchTheApplication -->
        <test-method signature="validateAllErrorMessages(java.util.HashMap)[pri:0, instance:testCases.ErrorValidations@503ecb24]" started-at="2025-01-24T18:05:05Z" name="validateAllErrorMessages" data-provider="getData" finished-at="2025-01-24T18:05:07Z" duration-ms="2133" status="FAIL">
          <params>
            <param index="0">
              <value>
                <![CDATA[{loginData=missingAtSymbol.com}]]>
              </value>
            </param>
          </params>
          <exception class="java.lang.AssertionError">
            <message>
              <![CDATA[expected [true] but found [false]]]>
            </message>
            <full-stacktrace>
              <![CDATA[java.lang.AssertionError: expected [true] but found [false]
at org.testng.Assert.fail(Assert.java:96)
at org.testng.Assert.failNotEquals(Assert.java:776)
at org.testng.Assert.assertTrue(Assert.java:44)
at org.testng.Assert.assertTrue(Assert.java:54)
at testCases.ErrorValidations.validateAllErrorMessages(ErrorValidations.java:35)
at java.base/jdk.internal.reflect.DirectMethodHandleAccessor.invoke(DirectMethodHandleAccessor.java:104)
at java.base/java.lang.reflect.Method.invoke(Method.java:577)
at org.testng.internal.MethodInvocationHelper.invokeMethod(MethodInvocationHelper.java:124)
at org.testng.internal.Invoker.invokeMethod(Invoker.java:583)
at org.testng.internal.Invoker.invokeTestMethod(Invoker.java:719)
at org.testng.internal.Invoker.invokeTestMethods(Invoker.java:989)
at org.testng.internal.TestMethodWorker.invokeTestMethods(TestMethodWorker.java:125)
at org.testng.internal.TestMethodWorker.run(TestMethodWorker.java:109)
at org.testng.TestRunner.privateRun(TestRunner.java:648)
at org.testng.TestRunner.run(TestRunner.java:505)
at org.testng.SuiteRunner.runTest(SuiteRunner.java:455)
at org.testng.SuiteRunner.access$000(SuiteRunner.java:40)
at org.testng.SuiteRunner$SuiteWorker.run(SuiteRunner.java:489)
at org.testng.internal.thread.ThreadUtil$1.call(ThreadUtil.java:52)
at java.base/java.util.concurrent.FutureTask.run(FutureTask.java:264)
at java.base/java.util.concurrent.ThreadPoolExecutor.runWorker(ThreadPoolExecutor.java:1136)
at java.base/java.util.concurrent.ThreadPoolExecutor$Worker.run(ThreadPoolExecutor.java:635)
at java.base/java.lang.Thread.run(Thread.java:833)
]]>
            </full-stacktrace>
          </exception> <!-- java.lang.AssertionError -->
          <reporter-output>
          </reporter-output>
        </test-method> <!-- validateAllErrorMessages -->
        <test-method is-config="true" signature="launchTheApplication()[pri:0, instance:testCases.ErrorValidations@503ecb24]" started-at="2025-01-24T18:05:07Z" name="launchTheApplication" finished-at="2025-01-24T18:05:12Z" duration-ms="5157" status="PASS">
          <reporter-output>
          </reporter-output>
        </test-method> <!-- launchTheApplication -->
        <test-method signature="validateAllErrorMessages(java.util.HashMap)[pri:0, instance:testCases.ErrorValidations@503ecb24]" started-at="2025-01-24T18:05:12Z" name="validateAllErrorMessages" data-provider="getData" finished-at="2025-01-24T18:05:14Z" duration-ms="2182" status="FAIL">
          <params>
            <param index="0">
              <value>
                <![CDATA[{loginData=missingAtSymbol.com}]]>
              </value>
            </param>
          </params>
          <exception class="java.lang.AssertionError">
            <message>
              <![CDATA[expected [true] but found [false]]]>
            </message>
            <full-stacktrace>
              <![CDATA[java.lang.AssertionError: expected [true] but found [false]
at org.testng.Assert.fail(Assert.java:96)
at org.testng.Assert.failNotEquals(Assert.java:776)
at org.testng.Assert.assertTrue(Assert.java:44)
at org.testng.Assert.assertTrue(Assert.java:54)
at testCases.ErrorValidations.validateAllErrorMessages(ErrorValidations.java:35)
at java.base/jdk.internal.reflect.DirectMethodHandleAccessor.invoke(DirectMethodHandleAccessor.java:104)
at java.base/java.lang.reflect.Method.invoke(Method.java:577)
at org.testng.internal.MethodInvocationHelper.invokeMethod(MethodInvocationHelper.java:124)
at org.testng.internal.Invoker.invokeMethod(Invoker.java:583)
at org.testng.internal.Invoker.retryFailed(Invoker.java:839)
at org.testng.internal.Invoker.invokeTestMethods(Invoker.java:1010)
at org.testng.internal.TestMethodWorker.invokeTestMethods(TestMethodWorker.java:125)
at org.testng.internal.TestMethodWorker.run(TestMethodWorker.java:109)
at org.testng.TestRunner.privateRun(TestRunner.java:648)
at org.testng.TestRunner.run(TestRunner.java:505)
at org.testng.SuiteRunner.runTest(SuiteRunner.java:455)
at org.testng.SuiteRunner.access$000(SuiteRunner.java:40)
at org.testng.SuiteRunner$SuiteWorker.run(SuiteRunner.java:489)
at org.testng.internal.thread.ThreadUtil$1.call(ThreadUtil.java:52)
at java.base/java.util.concurrent.FutureTask.run(FutureTask.java:264)
at java.base/java.util.concurrent.ThreadPoolExecutor.runWorker(ThreadPoolExecutor.java:1136)
at java.base/java.util.concurrent.ThreadPoolExecutor$Worker.run(ThreadPoolExecutor.java:635)
at java.base/java.lang.Thread.run(Thread.java:833)
]]>
            </full-stacktrace>
          </exception> <!-- java.lang.AssertionError -->
          <reporter-output>
          </reporter-output>
        </test-method> <!-- validateAllErrorMessages -->
        <test-method is-config="true" signature="launchTheApplication()[pri:0, instance:testCases.ErrorValidations@503ecb24]" started-at="2025-01-24T18:05:15Z" name="launchTheApplication" finished-at="2025-01-24T18:05:20Z" duration-ms="5159" status="PASS">
          <reporter-output>
          </reporter-output>
        </test-method> <!-- launchTheApplication -->
        <test-method signature="validateAllErrorMessages(java.util.HashMap)[pri:0, instance:testCases.ErrorValidations@503ecb24]" started-at="2025-01-24T18:05:20Z" name="validateAllErrorMessages" data-provider="getData" finished-at="2025-01-24T18:05:22Z" duration-ms="2109" status="FAIL">
          <params>
            <param index="0">
              <value>
                <![CDATA[{loginData=invalidEmail@domain}]]>
              </value>
            </param>
          </params>
          <exception class="java.lang.AssertionError">
            <message>
              <![CDATA[expected [true] but found [false]]]>
            </message>
            <full-stacktrace>
              <![CDATA[java.lang.AssertionError: expected [true] but found [false]
at org.testng.Assert.fail(Assert.java:96)
at org.testng.Assert.failNotEquals(Assert.java:776)
at org.testng.Assert.assertTrue(Assert.java:44)
at org.testng.Assert.assertTrue(Assert.java:54)
at testCases.ErrorValidations.validateAllErrorMessages(ErrorValidations.java:35)
at java.base/jdk.internal.reflect.DirectMethodHandleAccessor.invoke(DirectMethodHandleAccessor.java:104)
at java.base/java.lang.reflect.Method.invoke(Method.java:577)
at org.testng.internal.MethodInvocationHelper.invokeMethod(MethodInvocationHelper.java:124)
at org.testng.internal.Invoker.invokeMethod(Invoker.java:583)
at org.testng.internal.Invoker.invokeTestMethod(Invoker.java:719)
at org.testng.internal.Invoker.invokeTestMethods(Invoker.java:989)
at org.testng.internal.TestMethodWorker.invokeTestMethods(TestMethodWorker.java:125)
at org.testng.internal.TestMethodWorker.run(TestMethodWorker.java:109)
at org.testng.TestRunner.privateRun(TestRunner.java:648)
at org.testng.TestRunner.run(TestRunner.java:505)
at org.testng.SuiteRunner.runTest(SuiteRunner.java:455)
at org.testng.SuiteRunner.access$000(SuiteRunner.java:40)
at org.testng.SuiteRunner$SuiteWorker.run(SuiteRunner.java:489)
at org.testng.internal.thread.ThreadUtil$1.call(ThreadUtil.java:52)
at java.base/java.util.concurrent.FutureTask.run(FutureTask.java:264)
at java.base/java.util.concurrent.ThreadPoolExecutor.runWorker(ThreadPoolExecutor.java:1136)
at java.base/java.util.concurrent.ThreadPoolExecutor$Worker.run(ThreadPoolExecutor.java:635)
at java.base/java.lang.Thread.run(Thread.java:833)
]]>
            </full-stacktrace>
          </exception> <!-- java.lang.AssertionError -->
          <reporter-output>
          </reporter-output>
        </test-method> <!-- validateAllErrorMessages -->
        <test-method is-config="true" signature="launchTheApplication()[pri:0, instance:testCases.ErrorValidations@503ecb24]" started-at="2025-01-24T18:05:22Z" name="launchTheApplication" finished-at="2025-01-24T18:05:28Z" duration-ms="5660" status="PASS">
          <reporter-output>
          </reporter-output>
        </test-method> <!-- launchTheApplication -->
        <test-method signature="validateAllErrorMessages(java.util.HashMap)[pri:0, instance:testCases.ErrorValidations@503ecb24]" started-at="2025-01-24T18:05:28Z" name="validateAllErrorMessages" data-provider="getData" finished-at="2025-01-24T18:05:30Z" duration-ms="2361" status="FAIL">
          <params>
            <param index="0">
              <value>
                <![CDATA[{loginData=invalidEmail@domain}]]>
              </value>
            </param>
          </params>
          <exception class="java.lang.AssertionError">
            <message>
              <![CDATA[expected [true] but found [false]]]>
            </message>
            <full-stacktrace>
              <![CDATA[java.lang.AssertionError: expected [true] but found [false]
at org.testng.Assert.fail(Assert.java:96)
at org.testng.Assert.failNotEquals(Assert.java:776)
at org.testng.Assert.assertTrue(Assert.java:44)
at org.testng.Assert.assertTrue(Assert.java:54)
at testCases.ErrorValidations.validateAllErrorMessages(ErrorValidations.java:35)
at java.base/jdk.internal.reflect.DirectMethodHandleAccessor.invoke(DirectMethodHandleAccessor.java:104)
at java.base/java.lang.reflect.Method.invoke(Method.java:577)
at org.testng.internal.MethodInvocationHelper.invokeMethod(MethodInvocationHelper.java:124)
at org.testng.internal.Invoker.invokeMethod(Invoker.java:583)
at org.testng.internal.Invoker.retryFailed(Invoker.java:839)
at org.testng.internal.Invoker.invokeTestMethods(Invoker.java:1010)
at org.testng.internal.TestMethodWorker.invokeTestMethods(TestMethodWorker.java:125)
at org.testng.internal.TestMethodWorker.run(TestMethodWorker.java:109)
at org.testng.TestRunner.privateRun(TestRunner.java:648)
at org.testng.TestRunner.run(TestRunner.java:505)
at org.testng.SuiteRunner.runTest(SuiteRunner.java:455)
at org.testng.SuiteRunner.access$000(SuiteRunner.java:40)
at org.testng.SuiteRunner$SuiteWorker.run(SuiteRunner.java:489)
at org.testng.internal.thread.ThreadUtil$1.call(ThreadUtil.java:52)
at java.base/java.util.concurrent.FutureTask.run(FutureTask.java:264)
at java.base/java.util.concurrent.ThreadPoolExecutor.runWorker(ThreadPoolExecutor.java:1136)
at java.base/java.util.concurrent.ThreadPoolExecutor$Worker.run(ThreadPoolExecutor.java:635)
at java.base/java.lang.Thread.run(Thread.java:833)
]]>
            </full-stacktrace>
          </exception> <!-- java.lang.AssertionError -->
          <reporter-output>
          </reporter-output>
        </test-method> <!-- validateAllErrorMessages -->
        <test-method is-config="true" signature="launchTheApplication()[pri:0, instance:testCases.ErrorValidations@503ecb24]" started-at="2025-01-24T18:05:30Z" name="launchTheApplication" finished-at="2025-01-24T18:05:35Z" duration-ms="5208" status="PASS">
          <reporter-output>
          </reporter-output>
        </test-method> <!-- launchTheApplication -->
        <test-method signature="validateAllErrorMessages(java.util.HashMap)[pri:0, instance:testCases.ErrorValidations@503ecb24]" started-at="2025-01-24T18:05:35Z" name="validateAllErrorMessages" data-provider="getData" finished-at="2025-01-24T18:05:38Z" duration-ms="2269" status="FAIL">
          <params>
            <param index="0">
              <value>
                <![CDATA[{loginData=@domain.com}]]>
              </value>
            </param>
          </params>
          <exception class="java.lang.AssertionError">
            <message>
              <![CDATA[expected [true] but found [false]]]>
            </message>
            <full-stacktrace>
              <![CDATA[java.lang.AssertionError: expected [true] but found [false]
at org.testng.Assert.fail(Assert.java:96)
at org.testng.Assert.failNotEquals(Assert.java:776)
at org.testng.Assert.assertTrue(Assert.java:44)
at org.testng.Assert.assertTrue(Assert.java:54)
at testCases.ErrorValidations.validateAllErrorMessages(ErrorValidations.java:35)
at java.base/jdk.internal.reflect.DirectMethodHandleAccessor.invoke(DirectMethodHandleAccessor.java:104)
at java.base/java.lang.reflect.Method.invoke(Method.java:577)
at org.testng.internal.MethodInvocationHelper.invokeMethod(MethodInvocationHelper.java:124)
at org.testng.internal.Invoker.invokeMethod(Invoker.java:583)
at org.testng.internal.Invoker.invokeTestMethod(Invoker.java:719)
at org.testng.internal.Invoker.invokeTestMethods(Invoker.java:989)
at org.testng.internal.TestMethodWorker.invokeTestMethods(TestMethodWorker.java:125)
at org.testng.internal.TestMethodWorker.run(TestMethodWorker.java:109)
at org.testng.TestRunner.privateRun(TestRunner.java:648)
at org.testng.TestRunner.run(TestRunner.java:505)
at org.testng.SuiteRunner.runTest(SuiteRunner.java:455)
at org.testng.SuiteRunner.access$000(SuiteRunner.java:40)
at org.testng.SuiteRunner$SuiteWorker.run(SuiteRunner.java:489)
at org.testng.internal.thread.ThreadUtil$1.call(ThreadUtil.java:52)
at java.base/java.util.concurrent.FutureTask.run(FutureTask.java:264)
at java.base/java.util.concurrent.ThreadPoolExecutor.runWorker(ThreadPoolExecutor.java:1136)
at java.base/java.util.concurrent.ThreadPoolExecutor$Worker.run(ThreadPoolExecutor.java:635)
at java.base/java.lang.Thread.run(Thread.java:833)
]]>
            </full-stacktrace>
          </exception> <!-- java.lang.AssertionError -->
          <reporter-output>
          </reporter-output>
        </test-method> <!-- validateAllErrorMessages -->
        <test-method is-config="true" signature="launchTheApplication()[pri:0, instance:testCases.ErrorValidations@503ecb24]" started-at="2025-01-24T18:05:38Z" name="launchTheApplication" finished-at="2025-01-24T18:05:43Z" duration-ms="5159" status="PASS">
          <reporter-output>
          </reporter-output>
        </test-method> <!-- launchTheApplication -->
        <test-method signature="validateAllErrorMessages(java.util.HashMap)[pri:0, instance:testCases.ErrorValidations@503ecb24]" started-at="2025-01-24T18:05:43Z" name="validateAllErrorMessages" data-provider="getData" finished-at="2025-01-24T18:05:45Z" duration-ms="2161" status="FAIL">
          <params>
            <param index="0">
              <value>
                <![CDATA[{loginData=@domain.com}]]>
              </value>
            </param>
          </params>
          <exception class="java.lang.AssertionError">
            <message>
              <![CDATA[expected [true] but found [false]]]>
            </message>
            <full-stacktrace>
              <![CDATA[java.lang.AssertionError: expected [true] but found [false]
at org.testng.Assert.fail(Assert.java:96)
at org.testng.Assert.failNotEquals(Assert.java:776)
at org.testng.Assert.assertTrue(Assert.java:44)
at org.testng.Assert.assertTrue(Assert.java:54)
at testCases.ErrorValidations.validateAllErrorMessages(ErrorValidations.java:35)
at java.base/jdk.internal.reflect.DirectMethodHandleAccessor.invoke(DirectMethodHandleAccessor.java:104)
at java.base/java.lang.reflect.Method.invoke(Method.java:577)
at org.testng.internal.MethodInvocationHelper.invokeMethod(MethodInvocationHelper.java:124)
at org.testng.internal.Invoker.invokeMethod(Invoker.java:583)
at org.testng.internal.Invoker.retryFailed(Invoker.java:839)
at org.testng.internal.Invoker.invokeTestMethods(Invoker.java:1010)
at org.testng.internal.TestMethodWorker.invokeTestMethods(TestMethodWorker.java:125)
at org.testng.internal.TestMethodWorker.run(TestMethodWorker.java:109)
at org.testng.TestRunner.privateRun(TestRunner.java:648)
at org.testng.TestRunner.run(TestRunner.java:505)
at org.testng.SuiteRunner.runTest(SuiteRunner.java:455)
at org.testng.SuiteRunner.access$000(SuiteRunner.java:40)
at org.testng.SuiteRunner$SuiteWorker.run(SuiteRunner.java:489)
at org.testng.internal.thread.ThreadUtil$1.call(ThreadUtil.java:52)
at java.base/java.util.concurrent.FutureTask.run(FutureTask.java:264)
at java.base/java.util.concurrent.ThreadPoolExecutor.runWorker(ThreadPoolExecutor.java:1136)
at java.base/java.util.concurrent.ThreadPoolExecutor$Worker.run(ThreadPoolExecutor.java:635)
at java.base/java.lang.Thread.run(Thread.java:833)
]]>
            </full-stacktrace>
          </exception> <!-- java.lang.AssertionError -->
          <reporter-output>
          </reporter-output>
        </test-method> <!-- validateAllErrorMessages -->
        <test-method is-config="true" signature="launchTheApplication()[pri:0, instance:testCases.ErrorValidations@503ecb24]" started-at="2025-01-24T18:05:45Z" name="launchTheApplication" finished-at="2025-01-24T18:05:50Z" duration-ms="5147" status="PASS">
          <reporter-output>
          </reporter-output>
        </test-method> <!-- launchTheApplication -->
        <test-method signature="validateAllErrorMessages(java.util.HashMap)[pri:0, instance:testCases.ErrorValidations@503ecb24]" started-at="2025-01-24T18:05:50Z" name="validateAllErrorMessages" data-provider="getData" finished-at="2025-01-24T18:05:53Z" duration-ms="2422" status="PASS">
          <params>
            <param index="0">
              <value>
                <![CDATA[{loginData=3453454454534535434}]]>
              </value>
            </param>
          </params>
          <reporter-output>
          </reporter-output>
        </test-method> <!-- validateAllErrorMessages -->
        <test-method is-config="true" signature="launchTheApplication()[pri:0, instance:testCases.ErrorValidations@503ecb24]" started-at="2025-01-24T18:05:53Z" name="launchTheApplication" finished-at="2025-01-24T18:05:58Z" duration-ms="5032" status="PASS">
          <reporter-output>
          </reporter-output>
        </test-method> <!-- launchTheApplication -->
        <test-method signature="validateAllErrorMessages(java.util.HashMap)[pri:0, instance:testCases.ErrorValidations@503ecb24]" started-at="2025-01-24T18:05:58Z" name="validateAllErrorMessages" data-provider="getData" finished-at="2025-01-24T18:06:00Z" duration-ms="2101" status="FAIL">
          <params>
            <param index="0">
              <value>
                <![CDATA[{loginData=12345abc}]]>
              </value>
            </param>
          </params>
          <exception class="java.lang.AssertionError">
            <message>
              <![CDATA[expected [true] but found [false]]]>
            </message>
            <full-stacktrace>
              <![CDATA[java.lang.AssertionError: expected [true] but found [false]
at org.testng.Assert.fail(Assert.java:96)
at org.testng.Assert.failNotEquals(Assert.java:776)
at org.testng.Assert.assertTrue(Assert.java:44)
at org.testng.Assert.assertTrue(Assert.java:54)
at testCases.ErrorValidations.validateAllErrorMessages(ErrorValidations.java:35)
at java.base/jdk.internal.reflect.DirectMethodHandleAccessor.invoke(DirectMethodHandleAccessor.java:104)
at java.base/java.lang.reflect.Method.invoke(Method.java:577)
at org.testng.internal.MethodInvocationHelper.invokeMethod(MethodInvocationHelper.java:124)
at org.testng.internal.Invoker.invokeMethod(Invoker.java:583)
at org.testng.internal.Invoker.invokeTestMethod(Invoker.java:719)
at org.testng.internal.Invoker.invokeTestMethods(Invoker.java:989)
at org.testng.internal.TestMethodWorker.invokeTestMethods(TestMethodWorker.java:125)
at org.testng.internal.TestMethodWorker.run(TestMethodWorker.java:109)
at org.testng.TestRunner.privateRun(TestRunner.java:648)
at org.testng.TestRunner.run(TestRunner.java:505)
at org.testng.SuiteRunner.runTest(SuiteRunner.java:455)
at org.testng.SuiteRunner.access$000(SuiteRunner.java:40)
at org.testng.SuiteRunner$SuiteWorker.run(SuiteRunner.java:489)
at org.testng.internal.thread.ThreadUtil$1.call(ThreadUtil.java:52)
at java.base/java.util.concurrent.FutureTask.run(FutureTask.java:264)
at java.base/java.util.concurrent.ThreadPoolExecutor.runWorker(ThreadPoolExecutor.java:1136)
at java.base/java.util.concurrent.ThreadPoolExecutor$Worker.run(ThreadPoolExecutor.java:635)
at java.base/java.lang.Thread.run(Thread.java:833)
]]>
            </full-stacktrace>
          </exception> <!-- java.lang.AssertionError -->
          <reporter-output>
          </reporter-output>
        </test-method> <!-- validateAllErrorMessages -->
        <test-method is-config="true" signature="launchTheApplication()[pri:0, instance:testCases.ErrorValidations@503ecb24]" started-at="2025-01-24T18:06:00Z" name="launchTheApplication" finished-at="2025-01-24T18:06:05Z" duration-ms="5027" status="PASS">
          <reporter-output>
          </reporter-output>
        </test-method> <!-- launchTheApplication -->
        <test-method signature="validateAllErrorMessages(java.util.HashMap)[pri:0, instance:testCases.ErrorValidations@503ecb24]" started-at="2025-01-24T18:06:05Z" name="validateAllErrorMessages" data-provider="getData" finished-at="2025-01-24T18:06:07Z" duration-ms="2112" status="FAIL">
          <params>
            <param index="0">
              <value>
                <![CDATA[{loginData=12345abc}]]>
              </value>
            </param>
          </params>
          <exception class="java.lang.AssertionError">
            <message>
              <![CDATA[expected [true] but found [false]]]>
            </message>
            <full-stacktrace>
              <![CDATA[java.lang.AssertionError: expected [true] but found [false]
at org.testng.Assert.fail(Assert.java:96)
at org.testng.Assert.failNotEquals(Assert.java:776)
at org.testng.Assert.assertTrue(Assert.java:44)
at org.testng.Assert.assertTrue(Assert.java:54)
at testCases.ErrorValidations.validateAllErrorMessages(ErrorValidations.java:35)
at java.base/jdk.internal.reflect.DirectMethodHandleAccessor.invoke(DirectMethodHandleAccessor.java:104)
at java.base/java.lang.reflect.Method.invoke(Method.java:577)
at org.testng.internal.MethodInvocationHelper.invokeMethod(MethodInvocationHelper.java:124)
at org.testng.internal.Invoker.invokeMethod(Invoker.java:583)
at org.testng.internal.Invoker.retryFailed(Invoker.java:839)
at org.testng.internal.Invoker.invokeTestMethods(Invoker.java:1010)
at org.testng.internal.TestMethodWorker.invokeTestMethods(TestMethodWorker.java:125)
at org.testng.internal.TestMethodWorker.run(TestMethodWorker.java:109)
at org.testng.TestRunner.privateRun(TestRunner.java:648)
at org.testng.TestRunner.run(TestRunner.java:505)
at org.testng.SuiteRunner.runTest(SuiteRunner.java:455)
at org.testng.SuiteRunner.access$000(SuiteRunner.java:40)
at org.testng.SuiteRunner$SuiteWorker.run(SuiteRunner.java:489)
at org.testng.internal.thread.ThreadUtil$1.call(ThreadUtil.java:52)
at java.base/java.util.concurrent.FutureTask.run(FutureTask.java:264)
at java.base/java.util.concurrent.ThreadPoolExecutor.runWorker(ThreadPoolExecutor.java:1136)
at java.base/java.util.concurrent.ThreadPoolExecutor$Worker.run(ThreadPoolExecutor.java:635)
at java.base/java.lang.Thread.run(Thread.java:833)
]]>
            </full-stacktrace>
          </exception> <!-- java.lang.AssertionError -->
          <reporter-output>
          </reporter-output>
        </test-method> <!-- validateAllErrorMessages -->
        <test-method is-config="true" signature="launchTheApplication()[pri:0, instance:testCases.ErrorValidations@503ecb24]" started-at="2025-01-24T18:06:07Z" name="launchTheApplication" finished-at="2025-01-24T18:06:13Z" duration-ms="5174" status="PASS">
          <reporter-output>
          </reporter-output>
        </test-method> <!-- launchTheApplication -->
        <test-method signature="validateAllErrorMessages(java.util.HashMap)[pri:0, instance:testCases.ErrorValidations@503ecb24]" started-at="2025-01-24T18:06:13Z" name="validateAllErrorMessages" data-provider="getData" finished-at="2025-01-24T18:06:15Z" duration-ms="2118" status="FAIL">
          <params>
            <param index="0">
              <value>
                <![CDATA[{loginData=abc123456789}]]>
              </value>
            </param>
          </params>
          <exception class="java.lang.AssertionError">
            <message>
              <![CDATA[expected [true] but found [false]]]>
            </message>
            <full-stacktrace>
              <![CDATA[java.lang.AssertionError: expected [true] but found [false]
at org.testng.Assert.fail(Assert.java:96)
at org.testng.Assert.failNotEquals(Assert.java:776)
at org.testng.Assert.assertTrue(Assert.java:44)
at org.testng.Assert.assertTrue(Assert.java:54)
at testCases.ErrorValidations.validateAllErrorMessages(ErrorValidations.java:35)
at java.base/jdk.internal.reflect.DirectMethodHandleAccessor.invoke(DirectMethodHandleAccessor.java:104)
at java.base/java.lang.reflect.Method.invoke(Method.java:577)
at org.testng.internal.MethodInvocationHelper.invokeMethod(MethodInvocationHelper.java:124)
at org.testng.internal.Invoker.invokeMethod(Invoker.java:583)
at org.testng.internal.Invoker.invokeTestMethod(Invoker.java:719)
at org.testng.internal.Invoker.invokeTestMethods(Invoker.java:989)
at org.testng.internal.TestMethodWorker.invokeTestMethods(TestMethodWorker.java:125)
at org.testng.internal.TestMethodWorker.run(TestMethodWorker.java:109)
at org.testng.TestRunner.privateRun(TestRunner.java:648)
at org.testng.TestRunner.run(TestRunner.java:505)
at org.testng.SuiteRunner.runTest(SuiteRunner.java:455)
at org.testng.SuiteRunner.access$000(SuiteRunner.java:40)
at org.testng.SuiteRunner$SuiteWorker.run(SuiteRunner.java:489)
at org.testng.internal.thread.ThreadUtil$1.call(ThreadUtil.java:52)
at java.base/java.util.concurrent.FutureTask.run(FutureTask.java:264)
at java.base/java.util.concurrent.ThreadPoolExecutor.runWorker(ThreadPoolExecutor.java:1136)
at java.base/java.util.concurrent.ThreadPoolExecutor$Worker.run(ThreadPoolExecutor.java:635)
at java.base/java.lang.Thread.run(Thread.java:833)
]]>
            </full-stacktrace>
          </exception> <!-- java.lang.AssertionError -->
          <reporter-output>
          </reporter-output>
        </test-method> <!-- validateAllErrorMessages -->
        <test-method is-config="true" signature="launchTheApplication()[pri:0, instance:testCases.ErrorValidations@503ecb24]" started-at="2025-01-24T18:06:15Z" name="launchTheApplication" finished-at="2025-01-24T18:06:20Z" duration-ms="5177" status="PASS">
          <reporter-output>
          </reporter-output>
        </test-method> <!-- launchTheApplication -->
        <test-method signature="validateAllErrorMessages(java.util.HashMap)[pri:0, instance:testCases.ErrorValidations@503ecb24]" started-at="2025-01-24T18:06:20Z" name="validateAllErrorMessages" data-provider="getData" finished-at="2025-01-24T18:06:22Z" duration-ms="2119" status="FAIL">
          <params>
            <param index="0">
              <value>
                <![CDATA[{loginData=abc123456789}]]>
              </value>
            </param>
          </params>
          <exception class="java.lang.AssertionError">
            <message>
              <![CDATA[expected [true] but found [false]]]>
            </message>
            <full-stacktrace>
              <![CDATA[java.lang.AssertionError: expected [true] but found [false]
at org.testng.Assert.fail(Assert.java:96)
at org.testng.Assert.failNotEquals(Assert.java:776)
at org.testng.Assert.assertTrue(Assert.java:44)
at org.testng.Assert.assertTrue(Assert.java:54)
at testCases.ErrorValidations.validateAllErrorMessages(ErrorValidations.java:35)
at java.base/jdk.internal.reflect.DirectMethodHandleAccessor.invoke(DirectMethodHandleAccessor.java:104)
at java.base/java.lang.reflect.Method.invoke(Method.java:577)
at org.testng.internal.MethodInvocationHelper.invokeMethod(MethodInvocationHelper.java:124)
at org.testng.internal.Invoker.invokeMethod(Invoker.java:583)
at org.testng.internal.Invoker.retryFailed(Invoker.java:839)
at org.testng.internal.Invoker.invokeTestMethods(Invoker.java:1010)
at org.testng.internal.TestMethodWorker.invokeTestMethods(TestMethodWorker.java:125)
at org.testng.internal.TestMethodWorker.run(TestMethodWorker.java:109)
at org.testng.TestRunner.privateRun(TestRunner.java:648)
at org.testng.TestRunner.run(TestRunner.java:505)
at org.testng.SuiteRunner.runTest(SuiteRunner.java:455)
at org.testng.SuiteRunner.access$000(SuiteRunner.java:40)
at org.testng.SuiteRunner$SuiteWorker.run(SuiteRunner.java:489)
at org.testng.internal.thread.ThreadUtil$1.call(ThreadUtil.java:52)
at java.base/java.util.concurrent.FutureTask.run(FutureTask.java:264)
at java.base/java.util.concurrent.ThreadPoolExecutor.runWorker(ThreadPoolExecutor.java:1136)
at java.base/java.util.concurrent.ThreadPoolExecutor$Worker.run(ThreadPoolExecutor.java:635)
at java.base/java.lang.Thread.run(Thread.java:833)
]]>
            </full-stacktrace>
          </exception> <!-- java.lang.AssertionError -->
          <reporter-output>
          </reporter-output>
        </test-method> <!-- validateAllErrorMessages -->
        <test-method is-config="true" signature="launchTheApplication()[pri:0, instance:testCases.ErrorValidations@503ecb24]" started-at="2025-01-24T18:06:22Z" name="launchTheApplication" finished-at="2025-01-24T18:06:27Z" duration-ms="5061" status="PASS">
          <reporter-output>
          </reporter-output>
        </test-method> <!-- launchTheApplication -->
        <test-method signature="validateAllErrorMessages(java.util.HashMap)[pri:0, instance:testCases.ErrorValidations@503ecb24]" started-at="2025-01-24T18:06:27Z" name="validateAllErrorMessages" data-provider="getData" finished-at="2025-01-24T18:06:29Z" duration-ms="2098" status="FAIL">
          <params>
            <param index="0">
              <value>
                <![CDATA[{loginData=abc12345}]]>
              </value>
            </param>
          </params>
          <exception class="java.lang.AssertionError">
            <message>
              <![CDATA[expected [true] but found [false]]]>
            </message>
            <full-stacktrace>
              <![CDATA[java.lang.AssertionError: expected [true] but found [false]
at org.testng.Assert.fail(Assert.java:96)
at org.testng.Assert.failNotEquals(Assert.java:776)
at org.testng.Assert.assertTrue(Assert.java:44)
at org.testng.Assert.assertTrue(Assert.java:54)
at testCases.ErrorValidations.validateAllErrorMessages(ErrorValidations.java:35)
at java.base/jdk.internal.reflect.DirectMethodHandleAccessor.invoke(DirectMethodHandleAccessor.java:104)
at java.base/java.lang.reflect.Method.invoke(Method.java:577)
at org.testng.internal.MethodInvocationHelper.invokeMethod(MethodInvocationHelper.java:124)
at org.testng.internal.Invoker.invokeMethod(Invoker.java:583)
at org.testng.internal.Invoker.invokeTestMethod(Invoker.java:719)
at org.testng.internal.Invoker.invokeTestMethods(Invoker.java:989)
at org.testng.internal.TestMethodWorker.invokeTestMethods(TestMethodWorker.java:125)
at org.testng.internal.TestMethodWorker.run(TestMethodWorker.java:109)
at org.testng.TestRunner.privateRun(TestRunner.java:648)
at org.testng.TestRunner.run(TestRunner.java:505)
at org.testng.SuiteRunner.runTest(SuiteRunner.java:455)
at org.testng.SuiteRunner.access$000(SuiteRunner.java:40)
at org.testng.SuiteRunner$SuiteWorker.run(SuiteRunner.java:489)
at org.testng.internal.thread.ThreadUtil$1.call(ThreadUtil.java:52)
at java.base/java.util.concurrent.FutureTask.run(FutureTask.java:264)
at java.base/java.util.concurrent.ThreadPoolExecutor.runWorker(ThreadPoolExecutor.java:1136)
at java.base/java.util.concurrent.ThreadPoolExecutor$Worker.run(ThreadPoolExecutor.java:635)
at java.base/java.lang.Thread.run(Thread.java:833)
]]>
            </full-stacktrace>
          </exception> <!-- java.lang.AssertionError -->
          <reporter-output>
          </reporter-output>
        </test-method> <!-- validateAllErrorMessages -->
        <test-method is-config="true" signature="launchTheApplication()[pri:0, instance:testCases.ErrorValidations@503ecb24]" started-at="2025-01-24T18:06:29Z" name="launchTheApplication" finished-at="2025-01-24T18:06:35Z" duration-ms="5243" status="PASS">
          <reporter-output>
          </reporter-output>
        </test-method> <!-- launchTheApplication -->
        <test-method signature="validateAllErrorMessages(java.util.HashMap)[pri:0, instance:testCases.ErrorValidations@503ecb24]" started-at="2025-01-24T18:06:35Z" name="validateAllErrorMessages" data-provider="getData" finished-at="2025-01-24T18:06:37Z" duration-ms="2064" status="FAIL">
          <params>
            <param index="0">
              <value>
                <![CDATA[{loginData=abc12345}]]>
              </value>
            </param>
          </params>
          <exception class="java.lang.AssertionError">
            <message>
              <![CDATA[expected [true] but found [false]]]>
            </message>
            <full-stacktrace>
              <![CDATA[java.lang.AssertionError: expected [true] but found [false]
at org.testng.Assert.fail(Assert.java:96)
at org.testng.Assert.failNotEquals(Assert.java:776)
at org.testng.Assert.assertTrue(Assert.java:44)
at org.testng.Assert.assertTrue(Assert.java:54)
at testCases.ErrorValidations.validateAllErrorMessages(ErrorValidations.java:35)
at java.base/jdk.internal.reflect.DirectMethodHandleAccessor.invoke(DirectMethodHandleAccessor.java:104)
at java.base/java.lang.reflect.Method.invoke(Method.java:577)
at org.testng.internal.MethodInvocationHelper.invokeMethod(MethodInvocationHelper.java:124)
at org.testng.internal.Invoker.invokeMethod(Invoker.java:583)
at org.testng.internal.Invoker.retryFailed(Invoker.java:839)
at org.testng.internal.Invoker.invokeTestMethods(Invoker.java:1010)
at org.testng.internal.TestMethodWorker.invokeTestMethods(TestMethodWorker.java:125)
at org.testng.internal.TestMethodWorker.run(TestMethodWorker.java:109)
at org.testng.TestRunner.privateRun(TestRunner.java:648)
at org.testng.TestRunner.run(TestRunner.java:505)
at org.testng.SuiteRunner.runTest(SuiteRunner.java:455)
at org.testng.SuiteRunner.access$000(SuiteRunner.java:40)
at org.testng.SuiteRunner$SuiteWorker.run(SuiteRunner.java:489)
at org.testng.internal.thread.ThreadUtil$1.call(ThreadUtil.java:52)
at java.base/java.util.concurrent.FutureTask.run(FutureTask.java:264)
at java.base/java.util.concurrent.ThreadPoolExecutor.runWorker(ThreadPoolExecutor.java:1136)
at java.base/java.util.concurrent.ThreadPoolExecutor$Worker.run(ThreadPoolExecutor.java:635)
at java.base/java.lang.Thread.run(Thread.java:833)
]]>
            </full-stacktrace>
          </exception> <!-- java.lang.AssertionError -->
          <reporter-output>
          </reporter-output>
        </test-method> <!-- validateAllErrorMessages -->
        <test-method is-config="true" signature="launchTheApplication()[pri:0, instance:testCases.ErrorValidations@503ecb24]" started-at="2025-01-24T18:06:37Z" name="launchTheApplication" finished-at="2025-01-24T18:06:42Z" duration-ms="5186" status="PASS">
          <reporter-output>
          </reporter-output>
        </test-method> <!-- launchTheApplication -->
        <test-method signature="validateAllErrorMessages(java.util.HashMap)[pri:0, instance:testCases.ErrorValidations@503ecb24]" started-at="2025-01-24T18:06:42Z" name="validateAllErrorMessages" data-provider="getData" finished-at="2025-01-24T18:06:44Z" duration-ms="2097" status="FAIL">
          <params>
            <param index="0">
              <value>
                <![CDATA[{loginData=abcxyz}]]>
              </value>
            </param>
          </params>
          <exception class="java.lang.AssertionError">
            <message>
              <![CDATA[expected [true] but found [false]]]>
            </message>
            <full-stacktrace>
              <![CDATA[java.lang.AssertionError: expected [true] but found [false]
at org.testng.Assert.fail(Assert.java:96)
at org.testng.Assert.failNotEquals(Assert.java:776)
at org.testng.Assert.assertTrue(Assert.java:44)
at org.testng.Assert.assertTrue(Assert.java:54)
at testCases.ErrorValidations.validateAllErrorMessages(ErrorValidations.java:35)
at java.base/jdk.internal.reflect.DirectMethodHandleAccessor.invoke(DirectMethodHandleAccessor.java:104)
at java.base/java.lang.reflect.Method.invoke(Method.java:577)
at org.testng.internal.MethodInvocationHelper.invokeMethod(MethodInvocationHelper.java:124)
at org.testng.internal.Invoker.invokeMethod(Invoker.java:583)
at org.testng.internal.Invoker.invokeTestMethod(Invoker.java:719)
at org.testng.internal.Invoker.invokeTestMethods(Invoker.java:989)
at org.testng.internal.TestMethodWorker.invokeTestMethods(TestMethodWorker.java:125)
at org.testng.internal.TestMethodWorker.run(TestMethodWorker.java:109)
at org.testng.TestRunner.privateRun(TestRunner.java:648)
at org.testng.TestRunner.run(TestRunner.java:505)
at org.testng.SuiteRunner.runTest(SuiteRunner.java:455)
at org.testng.SuiteRunner.access$000(SuiteRunner.java:40)
at org.testng.SuiteRunner$SuiteWorker.run(SuiteRunner.java:489)
at org.testng.internal.thread.ThreadUtil$1.call(ThreadUtil.java:52)
at java.base/java.util.concurrent.FutureTask.run(FutureTask.java:264)
at java.base/java.util.concurrent.ThreadPoolExecutor.runWorker(ThreadPoolExecutor.java:1136)
at java.base/java.util.concurrent.ThreadPoolExecutor$Worker.run(ThreadPoolExecutor.java:635)
at java.base/java.lang.Thread.run(Thread.java:833)
]]>
            </full-stacktrace>
          </exception> <!-- java.lang.AssertionError -->
          <reporter-output>
          </reporter-output>
        </test-method> <!-- validateAllErrorMessages -->
        <test-method is-config="true" signature="launchTheApplication()[pri:0, instance:testCases.ErrorValidations@503ecb24]" started-at="2025-01-24T18:06:44Z" name="launchTheApplication" finished-at="2025-01-24T18:06:49Z" duration-ms="5097" status="PASS">
          <reporter-output>
          </reporter-output>
        </test-method> <!-- launchTheApplication -->
        <test-method signature="validateAllErrorMessages(java.util.HashMap)[pri:0, instance:testCases.ErrorValidations@503ecb24]" started-at="2025-01-24T18:06:49Z" name="validateAllErrorMessages" data-provider="getData" finished-at="2025-01-24T18:06:52Z" duration-ms="2202" status="FAIL">
          <params>
            <param index="0">
              <value>
                <![CDATA[{loginData=abcxyz}]]>
              </value>
            </param>
          </params>
          <exception class="java.lang.AssertionError">
            <message>
              <![CDATA[expected [true] but found [false]]]>
            </message>
            <full-stacktrace>
              <![CDATA[java.lang.AssertionError: expected [true] but found [false]
at org.testng.Assert.fail(Assert.java:96)
at org.testng.Assert.failNotEquals(Assert.java:776)
at org.testng.Assert.assertTrue(Assert.java:44)
at org.testng.Assert.assertTrue(Assert.java:54)
at testCases.ErrorValidations.validateAllErrorMessages(ErrorValidations.java:35)
at java.base/jdk.internal.reflect.DirectMethodHandleAccessor.invoke(DirectMethodHandleAccessor.java:104)
at java.base/java.lang.reflect.Method.invoke(Method.java:577)
at org.testng.internal.MethodInvocationHelper.invokeMethod(MethodInvocationHelper.java:124)
at org.testng.internal.Invoker.invokeMethod(Invoker.java:583)
at org.testng.internal.Invoker.retryFailed(Invoker.java:839)
at org.testng.internal.Invoker.invokeTestMethods(Invoker.java:1010)
at org.testng.internal.TestMethodWorker.invokeTestMethods(TestMethodWorker.java:125)
at org.testng.internal.TestMethodWorker.run(TestMethodWorker.java:109)
at org.testng.TestRunner.privateRun(TestRunner.java:648)
at org.testng.TestRunner.run(TestRunner.java:505)
at org.testng.SuiteRunner.runTest(SuiteRunner.java:455)
at org.testng.SuiteRunner.access$000(SuiteRunner.java:40)
at org.testng.SuiteRunner$SuiteWorker.run(SuiteRunner.java:489)
at org.testng.internal.thread.ThreadUtil$1.call(ThreadUtil.java:52)
at java.base/java.util.concurrent.FutureTask.run(FutureTask.java:264)
at java.base/java.util.concurrent.ThreadPoolExecutor.runWorker(ThreadPoolExecutor.java:1136)
at java.base/java.util.concurrent.ThreadPoolExecutor$Worker.run(ThreadPoolExecutor.java:635)
at java.base/java.lang.Thread.run(Thread.java:833)
]]>
            </full-stacktrace>
          </exception> <!-- java.lang.AssertionError -->
          <reporter-output>
          </reporter-output>
        </test-method> <!-- validateAllErrorMessages -->
        <test-method is-config="true" signature="tearDown()[pri:0, instance:testCases.ErrorValidations@503ecb24]" started-at="2025-01-24T18:06:52Z" name="tearDown" finished-at="2025-01-24T18:06:52Z" duration-ms="197" status="PASS">
          <reporter-output>
          </reporter-output>
        </test-method> <!-- tearDown -->
      </class> <!-- testCases.ErrorValidations -->
    </test> <!-- Error Validations -->
  </suite> <!-- Suite -->
</testng-results>
